ERROR 2023-09-20 13:20:10,917 log 19968 25528 Internal Server Error: /leads-collector/1
Traceback (most recent call last):
  File "C:\Python39\lib\site-packages\django\core\handlers\exception.py", line 34, in inner
    response = get_response(request)
  File "C:\Python39\lib\site-packages\django\core\handlers\base.py", line 115, in _get_response
    response = self.process_exception_by_middleware(e, request)
  File "C:\Python39\lib\site-packages\django\core\handlers\base.py", line 113, in _get_response
    response = wrapped_callback(request, *callback_args, **callback_kwargs)
  File "E:\Clients\dbcampaign\developing_project\base\views.py", line 95, in leads_collector
    mail_sender("h","h","h")
  File "E:\Clients\dbcampaign\developing_project\base\tasks.py", line 8, in mail_sender
    send_mail(
  File "C:\Python39\lib\site-packages\django\core\mail\__init__.py", line 60, in send_mail
    return mail.send()
  File "C:\Python39\lib\site-packages\django\core\mail\message.py", line 276, in send
    return self.get_connection(fail_silently).send_messages([self])
  File "C:\Python39\lib\site-packages\django\core\mail\backends\smtp.py", line 102, in send_messages
    new_conn_created = self.open()
  File "C:\Python39\lib\site-packages\django\core\mail\backends\smtp.py", line 62, in open
    self.connection = self.connection_class(self.host, self.port, **connection_params)
  File "C:\Python39\lib\smtplib.py", line 255, in __init__
    (code, msg) = self.connect(host, port)
  File "C:\Python39\lib\smtplib.py", line 341, in connect
    self.sock = self._get_socket(host, port, self.timeout)
  File "C:\Python39\lib\smtplib.py", line 312, in _get_socket
    return socket.create_connection((host, port), timeout,
  File "C:\Python39\lib\socket.py", line 823, in create_connection
    for res in getaddrinfo(host, port, 0, SOCK_STREAM):
  File "C:\Python39\lib\socket.py", line 954, in getaddrinfo
    for res in _socket.getaddrinfo(host, port, family, type, proto, flags):
socket.gaierror: [Errno 11001] getaddrinfo failed
ERROR 2023-09-20 13:20:10,922 basehttp 19968 25528 "POST /leads-collector/1 HTTP/1.1" 500 116866
ERROR 2023-09-20 13:23:16,941 log 3356 18784 Internal Server Error: /leads-collector/1
Traceback (most recent call last):
  File "C:\Python39\lib\site-packages\django\core\handlers\exception.py", line 34, in inner
    response = get_response(request)
  File "C:\Python39\lib\site-packages\django\core\handlers\base.py", line 115, in _get_response
    response = self.process_exception_by_middleware(e, request)
  File "C:\Python39\lib\site-packages\django\core\handlers\base.py", line 113, in _get_response
    response = wrapped_callback(request, *callback_args, **callback_kwargs)
  File "E:\Clients\dbcampaign\developing_project\base\views.py", line 95, in leads_collector
    mail_sender("h","h","h")
  File "E:\Clients\dbcampaign\developing_project\base\tasks.py", line 8, in mail_sender
    send_mail(
  File "C:\Python39\lib\site-packages\django\core\mail\__init__.py", line 60, in send_mail
    return mail.send()
  File "C:\Python39\lib\site-packages\django\core\mail\message.py", line 276, in send
    return self.get_connection(fail_silently).send_messages([self])
  File "C:\Python39\lib\site-packages\django\core\mail\backends\smtp.py", line 102, in send_messages
    new_conn_created = self.open()
  File "C:\Python39\lib\site-packages\django\core\mail\backends\smtp.py", line 69, in open
    self.connection.login(self.username, self.password)
  File "C:\Python39\lib\smtplib.py", line 750, in login
    raise last_exception
  File "C:\Python39\lib\smtplib.py", line 739, in login
    (code, resp) = self.auth(
  File "C:\Python39\lib\smtplib.py", line 662, in auth
    raise SMTPAuthenticationError(code, resp)
smtplib.SMTPAuthenticationError: (535, b'5.7.8 Username and Password not accepted. Learn more at\n5.7.8  https://support.google.com/mail/?p=BadCredentials y20-20020a1c4b14000000b003feee8d8011sm1257057wma.41 - gsmtp')
ERROR 2023-09-20 13:23:16,945 basehttp 3356 18784 "POST /leads-collector/1 HTTP/1.1" 500 112337
ERROR 2023-09-20 13:28:05,938 log 3356 18784 Internal Server Error: /leads-collector/1
Traceback (most recent call last):
  File "C:\Python39\lib\site-packages\django\core\handlers\exception.py", line 34, in inner
    response = get_response(request)
  File "C:\Python39\lib\site-packages\django\core\handlers\base.py", line 115, in _get_response
    response = self.process_exception_by_middleware(e, request)
  File "C:\Python39\lib\site-packages\django\core\handlers\base.py", line 113, in _get_response
    response = wrapped_callback(request, *callback_args, **callback_kwargs)
  File "E:\Clients\dbcampaign\developing_project\base\views.py", line 95, in leads_collector
    mail_sender("h","h","h")
  File "E:\Clients\dbcampaign\developing_project\base\tasks.py", line 8, in mail_sender
    send_mail(
  File "C:\Python39\lib\site-packages\django\core\mail\__init__.py", line 60, in send_mail
    return mail.send()
  File "C:\Python39\lib\site-packages\django\core\mail\message.py", line 276, in send
    return self.get_connection(fail_silently).send_messages([self])
  File "C:\Python39\lib\site-packages\django\core\mail\backends\smtp.py", line 102, in send_messages
    new_conn_created = self.open()
  File "C:\Python39\lib\site-packages\django\core\mail\backends\smtp.py", line 69, in open
    self.connection.login(self.username, self.password)
  File "C:\Python39\lib\smtplib.py", line 750, in login
    raise last_exception
  File "C:\Python39\lib\smtplib.py", line 739, in login
    (code, resp) = self.auth(
  File "C:\Python39\lib\smtplib.py", line 662, in auth
    raise SMTPAuthenticationError(code, resp)
smtplib.SMTPAuthenticationError: (535, b'5.7.8 Username and Password not accepted. Learn more at\n5.7.8  https://support.google.com/mail/?p=BadCredentials k8-20020a5d4288000000b00317a29af4b2sm17835580wrq.68 - gsmtp')
ERROR 2023-09-20 13:28:05,941 basehttp 3356 18784 "POST /leads-collector/1 HTTP/1.1" 500 112337
ERROR 2023-09-22 13:58:07,720 log 23452 10092 Internal Server Error: /leads-collector/3
Traceback (most recent call last):
  File "C:\Python39\lib\site-packages\django\core\handlers\exception.py", line 34, in inner
    response = get_response(request)
  File "C:\Python39\lib\site-packages\django\core\handlers\base.py", line 115, in _get_response
    response = self.process_exception_by_middleware(e, request)
  File "C:\Python39\lib\site-packages\django\core\handlers\base.py", line 113, in _get_response
    response = wrapped_callback(request, *callback_args, **callback_kwargs)
  File "E:\Clients\dbcampaign\developing_project\base\views.py", line 96, in leads_collector
    mail_sender.delay(for_service.email_address_associate, for_service.email_address_password, for_service.receiver_email)
AttributeError: 'function' object has no attribute 'delay'
ERROR 2023-09-22 13:58:07,726 basehttp 23452 10092 "POST /leads-collector/3 HTTP/1.1" 500 74695
ERROR 2023-09-22 13:58:29,613 log 3616 24096 Internal Server Error: /leads-collector/3
Traceback (most recent call last):
  File "C:\Python39\lib\site-packages\django\core\handlers\exception.py", line 34, in inner
    response = get_response(request)
  File "C:\Python39\lib\site-packages\django\core\handlers\base.py", line 115, in _get_response
    response = self.process_exception_by_middleware(e, request)
  File "C:\Python39\lib\site-packages\django\core\handlers\base.py", line 113, in _get_response
    response = wrapped_callback(request, *callback_args, **callback_kwargs)
  File "E:\Clients\dbcampaign\developing_project\base\views.py", line 96, in leads_collector
    mail_sender(for_service.email_address_associate, for_service.email_address_password, for_service.receiver_email)
  File "E:\Clients\dbcampaign\developing_project\base\tasks.py", line 10, in mail_sender
    send_mail(
  File "C:\Python39\lib\site-packages\django\core\mail\__init__.py", line 60, in send_mail
    return mail.send()
  File "C:\Python39\lib\site-packages\django\core\mail\message.py", line 276, in send
    return self.get_connection(fail_silently).send_messages([self])
  File "C:\Python39\lib\site-packages\django\core\mail\backends\smtp.py", line 109, in send_messages
    sent = self._send(message)
  File "C:\Python39\lib\site-packages\django\core\mail\backends\smtp.py", line 125, in _send
    self.connection.sendmail(from_email, recipients, message.as_bytes(linesep='\r\n'))
  File "C:\Python39\lib\smtplib.py", line 887, in sendmail
    raise SMTPSenderRefused(code, resp, from_addr)
smtplib.SMTPSenderRefused: (530, b'5.7.0 Authentication Required. Learn more at\n5.7.0  https://support.google.com/mail/?p=WantAuthError y13-20020a5d470d000000b003217b1f6a2dsm3912214wrq.70 - gsmtp', 'ayaaninam555@gmail.com')
ERROR 2023-09-22 13:58:29,623 basehttp 3616 24096 "POST /leads-collector/3 HTTP/1.1" 500 102929
ERROR 2023-09-22 21:20:53,746 log 24836 8060 Internal Server Error: /
Traceback (most recent call last):
  File "C:\Python39\lib\site-packages\django\core\handlers\exception.py", line 34, in inner
    response = get_response(request)
  File "C:\Python39\lib\site-packages\django\core\handlers\base.py", line 115, in _get_response
    response = self.process_exception_by_middleware(e, request)
  File "C:\Python39\lib\site-packages\django\core\handlers\base.py", line 113, in _get_response
    response = wrapped_callback(request, *callback_args, **callback_kwargs)
  File "E:\Clients\dbcampaign\developing_project\base\views.py", line 22, in homepage
    return render(request, "homepage.html", context)
  File "C:\Python39\lib\site-packages\django\shortcuts.py", line 19, in render
    content = loader.render_to_string(template_name, context, request, using=using)
  File "C:\Python39\lib\site-packages\django\template\loader.py", line 62, in render_to_string
    return template.render(context, request)
  File "C:\Python39\lib\site-packages\django\template\backends\django.py", line 61, in render
    return self.template.render(context)
  File "C:\Python39\lib\site-packages\django\template\base.py", line 171, in render
    return self._render(context)
  File "C:\Python39\lib\site-packages\django\template\base.py", line 163, in _render
    return self.nodelist.render(context)
  File "C:\Python39\lib\site-packages\django\template\base.py", line 936, in render
    bit = node.render_annotated(context)
  File "C:\Python39\lib\site-packages\django\template\base.py", line 903, in render_annotated
    return self.render(context)
  File "C:\Python39\lib\site-packages\django\template\loader_tags.py", line 150, in render
    return compiled_parent._render(context)
  File "C:\Python39\lib\site-packages\django\template\base.py", line 163, in _render
    return self.nodelist.render(context)
  File "C:\Python39\lib\site-packages\django\template\base.py", line 936, in render
    bit = node.render_annotated(context)
  File "C:\Python39\lib\site-packages\django\template\base.py", line 903, in render_annotated
    return self.render(context)
  File "C:\Python39\lib\site-packages\django\template\defaulttags.py", line 443, in render
    url = reverse(view_name, args=args, kwargs=kwargs, current_app=current_app)
  File "C:\Python39\lib\site-packages\django\urls\base.py", line 87, in reverse
    return iri_to_uri(resolver._reverse_with_prefix(view, prefix, *args, **kwargs))
  File "C:\Python39\lib\site-packages\django\urls\resolvers.py", line 676, in _reverse_with_prefix
    raise NoReverseMatch(msg)
django.urls.exceptions.NoReverseMatch: Reverse for 'newsletter_emails_collector' not found. 'newsletter_emails_collector' is not a valid view function or pattern name.
ERROR 2023-09-22 21:20:53,787 basehttp 24836 8060 "GET / HTTP/1.1" 500 150587
ERROR 2023-09-22 21:22:53,529 log 16956 6136 Internal Server Error: /newsletter-emails-collector
Traceback (most recent call last):
  File "C:\Python39\lib\site-packages\django\db\backends\utils.py", line 86, in _execute
    return self.cursor.execute(sql, params)
  File "C:\Python39\lib\site-packages\django\db\backends\sqlite3\base.py", line 396, in execute
    return Database.Cursor.execute(self, query, params)
sqlite3.IntegrityError: NOT NULL constraint failed: base_newsletteremail.email_address

The above exception was the direct cause of the following exception:

Traceback (most recent call last):
  File "C:\Python39\lib\site-packages\django\core\handlers\exception.py", line 34, in inner
    response = get_response(request)
  File "C:\Python39\lib\site-packages\django\core\handlers\base.py", line 115, in _get_response
    response = self.process_exception_by_middleware(e, request)
  File "C:\Python39\lib\site-packages\django\core\handlers\base.py", line 113, in _get_response
    response = wrapped_callback(request, *callback_args, **callback_kwargs)
  File "E:\Clients\dbcampaign\developing_project\base\views.py", line 108, in newsletter_emails_collector
    NewsLetterEmail.objects.create(
  File "C:\Python39\lib\site-packages\django\db\models\manager.py", line 82, in manager_method
    return getattr(self.get_queryset(), name)(*args, **kwargs)
  File "C:\Python39\lib\site-packages\django\db\models\query.py", line 433, in create
    obj.save(force_insert=True, using=self.db)
  File "C:\Python39\lib\site-packages\django\db\models\base.py", line 745, in save
    self.save_base(using=using, force_insert=force_insert,
  File "C:\Python39\lib\site-packages\django\db\models\base.py", line 782, in save_base
    updated = self._save_table(
  File "C:\Python39\lib\site-packages\django\db\models\base.py", line 886, in _save_table
    results = self._do_insert(cls._base_manager, using, fields, returning_fields, raw)
  File "C:\Python39\lib\site-packages\django\db\models\base.py", line 923, in _do_insert
    return manager._insert(
  File "C:\Python39\lib\site-packages\django\db\models\manager.py", line 82, in manager_method
    return getattr(self.get_queryset(), name)(*args, **kwargs)
  File "C:\Python39\lib\site-packages\django\db\models\query.py", line 1204, in _insert
    return query.get_compiler(using=using).execute_sql(returning_fields)
  File "C:\Python39\lib\site-packages\django\db\models\sql\compiler.py", line 1377, in execute_sql
    cursor.execute(sql, params)
  File "C:\Python39\lib\site-packages\django\db\backends\utils.py", line 100, in execute
    return super().execute(sql, params)
  File "C:\Python39\lib\site-packages\django\db\backends\utils.py", line 68, in execute
    return self._execute_with_wrappers(sql, params, many=False, executor=self._execute)
  File "C:\Python39\lib\site-packages\django\db\backends\utils.py", line 77, in _execute_with_wrappers
    return executor(sql, params, many, context)
  File "C:\Python39\lib\site-packages\django\db\backends\utils.py", line 86, in _execute
    return self.cursor.execute(sql, params)
  File "C:\Python39\lib\site-packages\django\db\utils.py", line 90, in __exit__
    raise dj_exc_value.with_traceback(traceback) from exc_value
  File "C:\Python39\lib\site-packages\django\db\backends\utils.py", line 86, in _execute
    return self.cursor.execute(sql, params)
  File "C:\Python39\lib\site-packages\django\db\backends\sqlite3\base.py", line 396, in execute
    return Database.Cursor.execute(self, query, params)
django.db.utils.IntegrityError: NOT NULL constraint failed: base_newsletteremail.email_address
ERROR 2023-09-22 21:22:53,540 basehttp 16956 6136 "POST /newsletter-emails-collector HTTP/1.1" 500 157253
ERROR 2023-09-22 22:36:48,720 log 12372 16648 Internal Server Error: /
Traceback (most recent call last):
  File "C:\Python39\lib\site-packages\django\core\handlers\exception.py", line 34, in inner
    response = get_response(request)
  File "C:\Python39\lib\site-packages\django\core\handlers\base.py", line 115, in _get_response
    response = self.process_exception_by_middleware(e, request)
  File "C:\Python39\lib\site-packages\django\core\handlers\base.py", line 113, in _get_response
    response = wrapped_callback(request, *callback_args, **callback_kwargs)
  File "E:\Clients\dbcampaign\developing_project\base\views.py", line 22, in homepage
    return render(request, "homepage.html", context)
  File "C:\Python39\lib\site-packages\django\shortcuts.py", line 19, in render
    content = loader.render_to_string(template_name, context, request, using=using)
  File "C:\Python39\lib\site-packages\django\template\loader.py", line 61, in render_to_string
    template = get_template(template_name, using=using)
  File "C:\Python39\lib\site-packages\django\template\loader.py", line 15, in get_template
    return engine.get_template(template_name)
  File "C:\Python39\lib\site-packages\django\template\backends\django.py", line 34, in get_template
    return Template(self.engine.get_template(template_name), self)
  File "C:\Python39\lib\site-packages\django\template\engine.py", line 143, in get_template
    template, origin = self.find_template(template_name)
  File "C:\Python39\lib\site-packages\django\template\engine.py", line 125, in find_template
    template = loader.get_template(name, skip=skip)
  File "C:\Python39\lib\site-packages\django\template\loaders\base.py", line 29, in get_template
    return Template(
  File "C:\Python39\lib\site-packages\django\template\base.py", line 156, in __init__
    self.nodelist = self.compile_nodelist()
  File "C:\Python39\lib\site-packages\django\template\base.py", line 194, in compile_nodelist
    return parser.parse()
  File "C:\Python39\lib\site-packages\django\template\base.py", line 477, in parse
    raise self.error(token, e)
  File "C:\Python39\lib\site-packages\django\template\base.py", line 475, in parse
    compiled_result = compile_func(self, token)
  File "C:\Python39\lib\site-packages\django\template\loader_tags.py", line 266, in do_extends
    nodelist = parser.parse()
  File "C:\Python39\lib\site-packages\django\template\base.py", line 477, in parse
    raise self.error(token, e)
  File "C:\Python39\lib\site-packages\django\template\base.py", line 475, in parse
    compiled_result = compile_func(self, token)
  File "C:\Python39\lib\site-packages\django\template\loader_tags.py", line 209, in do_block
    nodelist = parser.parse(('endblock',))
  File "C:\Python39\lib\site-packages\django\template\base.py", line 448, in parse
    raise self.error(token, e)
  File "C:\Python39\lib\site-packages\django\template\base.py", line 446, in parse
    filter_expression = self.compile_filter(token.contents)
  File "C:\Python39\lib\site-packages\django\template\base.py", line 562, in compile_filter
    return FilterExpression(token, self)
  File "C:\Python39\lib\site-packages\django\template\base.py", line 661, in __init__
    raise TemplateSyntaxError("Could not parse the remainder: '%s' "
django.template.exceptions.TemplateSyntaxError: Could not parse the remainder: '(request.endpoint)' from 'url_for(request.endpoint)'
ERROR 2023-09-22 22:36:48,731 basehttp 12372 16648 "GET / HTTP/1.1" 500 175815
ERROR 2023-09-22 22:37:07,837 log 12372 16648 Internal Server Error: /
Traceback (most recent call last):
  File "C:\Python39\lib\site-packages\django\core\handlers\exception.py", line 34, in inner
    response = get_response(request)
  File "C:\Python39\lib\site-packages\django\core\handlers\base.py", line 115, in _get_response
    response = self.process_exception_by_middleware(e, request)
  File "C:\Python39\lib\site-packages\django\core\handlers\base.py", line 113, in _get_response
    response = wrapped_callback(request, *callback_args, **callback_kwargs)
  File "E:\Clients\dbcampaign\developing_project\base\views.py", line 22, in homepage
    return render(request, "homepage.html", context)
  File "C:\Python39\lib\site-packages\django\shortcuts.py", line 19, in render
    content = loader.render_to_string(template_name, context, request, using=using)
  File "C:\Python39\lib\site-packages\django\template\loader.py", line 61, in render_to_string
    template = get_template(template_name, using=using)
  File "C:\Python39\lib\site-packages\django\template\loader.py", line 15, in get_template
    return engine.get_template(template_name)
  File "C:\Python39\lib\site-packages\django\template\backends\django.py", line 34, in get_template
    return Template(self.engine.get_template(template_name), self)
  File "C:\Python39\lib\site-packages\django\template\engine.py", line 143, in get_template
    template, origin = self.find_template(template_name)
  File "C:\Python39\lib\site-packages\django\template\engine.py", line 125, in find_template
    template = loader.get_template(name, skip=skip)
  File "C:\Python39\lib\site-packages\django\template\loaders\base.py", line 29, in get_template
    return Template(
  File "C:\Python39\lib\site-packages\django\template\base.py", line 156, in __init__
    self.nodelist = self.compile_nodelist()
  File "C:\Python39\lib\site-packages\django\template\base.py", line 194, in compile_nodelist
    return parser.parse()
  File "C:\Python39\lib\site-packages\django\template\base.py", line 477, in parse
    raise self.error(token, e)
  File "C:\Python39\lib\site-packages\django\template\base.py", line 475, in parse
    compiled_result = compile_func(self, token)
  File "C:\Python39\lib\site-packages\django\template\loader_tags.py", line 266, in do_extends
    nodelist = parser.parse()
  File "C:\Python39\lib\site-packages\django\template\base.py", line 477, in parse
    raise self.error(token, e)
  File "C:\Python39\lib\site-packages\django\template\base.py", line 475, in parse
    compiled_result = compile_func(self, token)
  File "C:\Python39\lib\site-packages\django\template\loader_tags.py", line 209, in do_block
    nodelist = parser.parse(('endblock',))
  File "C:\Python39\lib\site-packages\django\template\base.py", line 448, in parse
    raise self.error(token, e)
  File "C:\Python39\lib\site-packages\django\template\base.py", line 446, in parse
    filter_expression = self.compile_filter(token.contents)
  File "C:\Python39\lib\site-packages\django\template\base.py", line 562, in compile_filter
    return FilterExpression(token, self)
  File "C:\Python39\lib\site-packages\django\template\base.py", line 661, in __init__
    raise TemplateSyntaxError("Could not parse the remainder: '%s' "
django.template.exceptions.TemplateSyntaxError: Could not parse the remainder: '(request.endpoint, **request.view_args)' from 'url_for(request.endpoint, **request.view_args)'
ERROR 2023-09-22 22:37:07,844 basehttp 12372 16648 "GET / HTTP/1.1" 500 176180
ERROR 2023-09-22 22:41:26,787 log 12372 12784 Internal Server Error: /services
Traceback (most recent call last):
  File "C:\Python39\lib\site-packages\django\template\base.py", line 469, in parse
    compile_func = self.tags[command]
KeyError: 'elseif'

During handling of the above exception, another exception occurred:

Traceback (most recent call last):
  File "C:\Python39\lib\site-packages\django\core\handlers\exception.py", line 34, in inner
    response = get_response(request)
  File "C:\Python39\lib\site-packages\django\core\handlers\base.py", line 115, in _get_response
    response = self.process_exception_by_middleware(e, request)
  File "C:\Python39\lib\site-packages\django\core\handlers\base.py", line 113, in _get_response
    response = wrapped_callback(request, *callback_args, **callback_kwargs)
  File "E:\Clients\dbcampaign\developing_project\base\views.py", line 37, in services_page
    return render(request, "services_page.html", context)
  File "C:\Python39\lib\site-packages\django\shortcuts.py", line 19, in render
    content = loader.render_to_string(template_name, context, request, using=using)
  File "C:\Python39\lib\site-packages\django\template\loader.py", line 62, in render_to_string
    return template.render(context, request)
  File "C:\Python39\lib\site-packages\django\template\backends\django.py", line 61, in render
    return self.template.render(context)
  File "C:\Python39\lib\site-packages\django\template\base.py", line 171, in render
    return self._render(context)
  File "C:\Python39\lib\site-packages\django\template\base.py", line 163, in _render
    return self.nodelist.render(context)
  File "C:\Python39\lib\site-packages\django\template\base.py", line 936, in render
    bit = node.render_annotated(context)
  File "C:\Python39\lib\site-packages\django\template\base.py", line 903, in render_annotated
    return self.render(context)
  File "C:\Python39\lib\site-packages\django\template\loader_tags.py", line 127, in render
    compiled_parent = self.get_parent(context)
  File "C:\Python39\lib\site-packages\django\template\loader_tags.py", line 124, in get_parent
    return self.find_template(parent, context)
  File "C:\Python39\lib\site-packages\django\template\loader_tags.py", line 103, in find_template
    template, origin = context.template.engine.find_template(
  File "C:\Python39\lib\site-packages\django\template\engine.py", line 125, in find_template
    template = loader.get_template(name, skip=skip)
  File "C:\Python39\lib\site-packages\django\template\loaders\base.py", line 29, in get_template
    return Template(
  File "C:\Python39\lib\site-packages\django\template\base.py", line 156, in __init__
    self.nodelist = self.compile_nodelist()
  File "C:\Python39\lib\site-packages\django\template\base.py", line 194, in compile_nodelist
    return parser.parse()
  File "C:\Python39\lib\site-packages\django\template\base.py", line 477, in parse
    raise self.error(token, e)
  File "C:\Python39\lib\site-packages\django\template\base.py", line 475, in parse
    compiled_result = compile_func(self, token)
  File "C:\Python39\lib\site-packages\django\template\defaulttags.py", line 952, in do_if
    nodelist = parser.parse(('elif', 'else', 'endif'))
  File "C:\Python39\lib\site-packages\django\template\base.py", line 471, in parse
    self.invalid_block_tag(token, command, parse_until)
  File "C:\Python39\lib\site-packages\django\template\base.py", line 521, in invalid_block_tag
    raise self.error(
django.template.exceptions.TemplateSyntaxError: Invalid block tag on line 55: 'elseif', expected 'elif', 'else' or 'endif'. Did you forget to register or load this tag?
ERROR 2023-09-22 22:41:26,802 basehttp 12372 12784 "GET /services HTTP/1.1" 500 184789
ERROR 2023-09-22 22:41:34,611 log 12372 12784 Internal Server Error: /services
Traceback (most recent call last):
  File "C:\Python39\lib\site-packages\django\core\handlers\exception.py", line 34, in inner
    response = get_response(request)
  File "C:\Python39\lib\site-packages\django\core\handlers\base.py", line 115, in _get_response
    response = self.process_exception_by_middleware(e, request)
  File "C:\Python39\lib\site-packages\django\core\handlers\base.py", line 113, in _get_response
    response = wrapped_callback(request, *callback_args, **callback_kwargs)
  File "E:\Clients\dbcampaign\developing_project\base\views.py", line 37, in services_page
    return render(request, "services_page.html", context)
  File "C:\Python39\lib\site-packages\django\shortcuts.py", line 19, in render
    content = loader.render_to_string(template_name, context, request, using=using)
  File "C:\Python39\lib\site-packages\django\template\loader.py", line 62, in render_to_string
    return template.render(context, request)
  File "C:\Python39\lib\site-packages\django\template\backends\django.py", line 61, in render
    return self.template.render(context)
  File "C:\Python39\lib\site-packages\django\template\base.py", line 171, in render
    return self._render(context)
  File "C:\Python39\lib\site-packages\django\template\base.py", line 163, in _render
    return self.nodelist.render(context)
  File "C:\Python39\lib\site-packages\django\template\base.py", line 936, in render
    bit = node.render_annotated(context)
  File "C:\Python39\lib\site-packages\django\template\base.py", line 903, in render_annotated
    return self.render(context)
  File "C:\Python39\lib\site-packages\django\template\loader_tags.py", line 127, in render
    compiled_parent = self.get_parent(context)
  File "C:\Python39\lib\site-packages\django\template\loader_tags.py", line 124, in get_parent
    return self.find_template(parent, context)
  File "C:\Python39\lib\site-packages\django\template\loader_tags.py", line 103, in find_template
    template, origin = context.template.engine.find_template(
  File "C:\Python39\lib\site-packages\django\template\engine.py", line 125, in find_template
    template = loader.get_template(name, skip=skip)
  File "C:\Python39\lib\site-packages\django\template\loaders\base.py", line 29, in get_template
    return Template(
  File "C:\Python39\lib\site-packages\django\template\base.py", line 156, in __init__
    self.nodelist = self.compile_nodelist()
  File "C:\Python39\lib\site-packages\django\template\base.py", line 194, in compile_nodelist
    return parser.parse()
  File "C:\Python39\lib\site-packages\django\template\base.py", line 477, in parse
    raise self.error(token, e)
  File "C:\Python39\lib\site-packages\django\template\base.py", line 475, in parse
    compiled_result = compile_func(self, token)
  File "C:\Python39\lib\site-packages\django\template\defaulttags.py", line 959, in do_if
    condition = TemplateIfParser(parser, bits).parse()
  File "C:\Python39\lib\site-packages\django\template\smartif.py", line 190, in parse
    retval = self.expression()
  File "C:\Python39\lib\site-packages\django\template\smartif.py", line 200, in expression
    left = t.nud(self)
  File "C:\Python39\lib\site-packages\django\template\smartif.py", line 144, in nud
    raise parser.error_class("Unexpected end of expression in if tag.")
django.template.exceptions.TemplateSyntaxError: Unexpected end of expression in if tag.
ERROR 2023-09-22 22:41:34,617 basehttp 12372 12784 "GET /services HTTP/1.1" 500 181066
